Workbook

Sheet README
A1: README — how this workbook is organised
A3: 25 sheets, grouped into 6 colour-coded families (tab colour = group). Start with START_HERE, then NAVIGATION_MAP for the full clickable index. This page is the one-stop explanation of what every sheet is and why it's coloured the way it is -- see CHANGELOG for what changed and when.
A5: Navigate
A6: =HYPERLINK("#START_HERE!A1","START_HERE") | B6: Landing page: what this workbook is, where to start.
A7: =HYPERLINK("#NAVIGATION_MAP!A1","NAVIGATION_MAP") | B7: Full sheet index with hyperlinks, one row per sheet, coloured by group.
A8: =HYPERLINK("#LISTS!A1","LISTS") | B8: Raw dropdown/reference lists used by data validation elsewhere.
A10: Overview
A11: =HYPERLINK("#DASHBOARD!A1","DASHBOARD") | B11: Top-line charts: Top-15 OFFER by S, Tier split, Category averages, full 50-item rank profile (with the item-7 spike explainer).
A12: =HYPERLINK("#DASHBOARD_2!A1","DASHBOARD_2") | B12: Secondary dashboard views.
A14: Live review / input
A15: =HYPERLINK("#EVALUATION_WORKSPACE!A1","EVALUATION_WORKSPACE") | B15: Main interaction sheet -- static rank read-only, reviewer input starts at STATUS columns.
A16: =HYPERLINK("#EVALUATION_INPUT!A1","EVALUATION_INPUT") | B16: Raw bidder input capture, feeds EVALUATION_WORKSPACE.
A17: =HYPERLINK("#NEGOTIATION_AGENDA!A1","NEGOTIATION_AGENDA") | B17: Talking points generated from low-status / high-S items, for negotiation prep.
A19: Rankings & trace
A20: =HYPERLINK("#OFFER_RANKING!A1","OFFER_RANKING") | B20: Static BT ranking of all 50 OFFER items -- the SSOT for OFFER importance.
A21: =HYPERLINK("#RTM_RANKING!A1","RTM_RANKING") | B21: Static BT ranking of all 722 RTM requirements -- the SSOT for RTM importance.
A22: =HYPERLINK("#RTM_CROSSWALK!A1","RTM_CROSSWALK") | B22: One row per OFFER<->RTM relationship (up to 66 per item) -- the full link detail behind OFFER_RANKING's condensed 'Primary RTMs' summary.
A23: =HYPERLINK("#RTM_REVIEW_QUEUE!A1","RTM_REVIEW_QUEUE") | B23: RTM rows flagged for reviewer attention, ordered by priority.
A24: =HYPERLINK("#RTM_LOOKUP!A1","RTM_LOOKUP") | B24: Pick one RTM, see everything about it on one screen.
A25: =HYPERLINK("#DOMAIN_SUMMARY!A1","DOMAIN_SUMMARY") | B25: RTM counts/tiers/avg S rolled up by Domain (22 domains).
A26: =HYPERLINK("#CLUSTERS!A1","CLUSTERS") | B26: The 8 classification clusters (C1-C8) and their member OFFER items.
A28: Reference / canonical
A29: =HYPERLINK("#OFFER_CANONICAL!A1","OFFER_CANONICAL") | B29: Original hand-curated source data for all 50 OFFER items -- read-only upstream of OFFER_RANKING.
A30: =HYPERLINK("#STANDARDS!A1","STANDARDS") | B30: Codes/standards register -- which RTM/OFFER items cite which external standard.
A31: =HYPERLINK("#DELIVERABLES!A1","DELIVERABLES") | B31: Per-OFFER-item evidence/fulfilment expectations.
A32: =HYPERLINK("#TAXONOMY!A1","TAXONOMY") | B32: Controlled vocabularies used throughout (Requirement Type, EPIC evidence-types, disposition, etc.) -- the single place these are DEFINED, reused elsewhere.
A33: =HYPERLINK("#COMPLIANCE_LEGEND!A1","COMPLIANCE_LEGEND") | B33: STATUS colour/label legend used on EVALUATION_WORKSPACE.
A34: =HYPERLINK("#WEIGHTS_METHOD!A1","WEIGHTS_METHOD") | B34: The 7 frozen BT weights (L/R/P/F/Q/LC/C), how Weighted S/BT Win %/BT λ are built, and the weight-sensitivity scenarios (static + live toggle).
A36: Governance / QC
A37: =HYPERLINK("#QUALITY_CHECKS!A1","QUALITY_CHECKS") | B37: Automated formula-integrity and cross-reference checks over the whole workbook.
A38: =HYPERLINK("#AUDIT_NOTES!A1","AUDIT_NOTES") | B38: Free-text audit trail of judgement calls made during data curation.
A39: =HYPERLINK("#DMAIC_AUDIT!A1","DMAIC_AUDIT") | B39: DMAIC-cycle traceability for this evaluation process itself.
A40: =HYPERLINK("#CODING_HANDOVER!A1","CODING_HANDOVER") | B40: Technical handover notes for whoever maintains this workbook next.

Sheet CHANGELOG
A1: CHANGELOG
A3: Version | B3: Major changes
A4: v8 | B4: DELIVERABLES!F evidence text rewritten from generic boilerplate to per-item RTM cross-reference + EPIC-keyed evidence type.
A5: v9 | B5: Full 722 RTM / 50 OFFER value-weighted Pareto and Focus Score analysis added to the HTML Navigator (Domain/Category/Cluster, for both RTM and OFFER).
A6: v10 | B6: RTM_CROSSWALK: added a real header row (row 4 was blank), fixed a misleading dark-navy fill on row 5 that looked like a header, added AutoFilter/frozen panes, and colour-coded relation types (Direct/Supporting/Broad/Contextual).
A7: v11 | B7: RTM_CROSSWALK: added headers for columns M/N (QC check, Source basis); rewrote 233 of 377 rows (62%) of column L from generic boilerplate to genuinely per-row text.
A8: v12 | B8: Excel window/zoom defaults set for 16:9 full-screen opening; per-sheet autozoom by column-count.
A9: v13 | B9: Tab-colour taxonomy: all 25 sheets assigned to 6 named groups; NAVIGATION_MAP extended with a colour-swatch legend column.
A10: v14 | B10: Nav-row column-clipping fixed across multiple sheets; Cost=70% weight-sensitivity scenario (static table) added to WEIGHTS_METHOD.
A11: v15 | B11: Technical Depth (EVALUATION_WORKSPACE R/X) colour-coded (soft pink/orange/green), deliberately paler than STATUS.
A12: v16 | B12: Gate column (Yes/No) recoloured to reuse the exact T0 Gate red across EVALUATION_WORKSPACE/OFFER_RANKING/RTM_RANKING; DASHBOARD's rank-profile chart got a callout explaining the item-7 spike (OFFER-09's S=55.67 entering rank 7, right after the 6 gate-precedence items).
A13: v17 | B13: STANDARDS!B lazy-boilerplate fixed (26 of 44 rows, grounded in linked RTM data); weight-dimension (L/R/P/F/Q/LC/C) colour legend + header comments added to OFFER_RANKING/RTM_RANKING/WEIGHTS_METHOD; all 7 raw dimension columns given a uniform 0-3 heatmap (previously only 3 of 7 had any colour) on both ranking sheets; live Cost-weight scenario toggle added (dropdown + formula-driven re-rank, no macro); new CATEGORY_FOCUS sheet (per-category top-ranked 'hidden champions' + Category x Cluster density heat maps, RTM and OFFER); README + this CHANGELOG sheet added.

Sheet START_HERE
A1: QPS OFFER evaluation workbook — v18 DMAIC-ready
A2: Use this workbook to rank fixed OFFER requirements, enter bidder evidence, and produce negotiation topics without mixing static importance with live review status.
A3: =HYPERLINK("#START_HERE!A1","Start") | B3: =HYPERLINK("#DASHBOARD!A1","Dashboard") | C3: =HYPERLINK("#EVALUATION_WORKSPACE!A1","Workspace") | D3: =HYPERLINK("#NEGOTIATION_AGENDA!A1","Agenda") | E3: =HYPERLINK("#OFFER_RANKING!A1","Ranking") | F3: =HYPERLINK("#RTM_CROSSWALK!A1","Crosswalk") | G3: =HYPERLINK("#QUALITY_CHECKS!A1","Quality") | H3: =HYPERLINK("#DMAIC_AUDIT!A1","DMAIC") | I3: =HYPERLINK("#CODING_HANDOVER!A1","Handover") | J3: =HYPERLINK("#RTM_RANKING!A1","RTM Rank") | K3: =HYPERLINK("#RTM_LOOKUP!A1","RTM Lookup") | L3: =HYPERLINK("#DASHBOARD_2!A1","Filter view") | M3: =HYPERLINK("#CLUSTERS!A1","Clusters") | N3: =HYPERLINK("#TAXONOMY!A1","Taxonomy")
A5: Step | B5: Sheet | C5: Purpose | D5: Action
A6: 1 | B6: =HYPERLINK("#DASHBOARD!A1","DASHBOARD") | C6: Read ranking shape and visual summary. | D6: No editing. Use for review meetings.
A7: 2 | B7: =HYPERLINK("#EVALUATION_WORKSPACE!A1","EVALUATION_WORKSPACE") | C7: Main reviewer workspace for Bidder A/B. | D7: Enter STATUS, Technical Depth, Source/Location, negotiation flag and comments.
A8: 3 | B8: =HYPERLINK("#NEGOTIATION_AGENDA!A1","NEGOTIATION_AGENDA") | C8: Filter the automatically mirrored A/B rows. | D8: Focus on RFI / missing / negotiation / not available rows.
A9: 4 | B9: =HYPERLINK("#OFFER_RANKING!A1","OFFER_RANKING") | C9: Audit static BT importance. | D9: Filter by tier, category, dimension, phase, standard or RTM.
A10: 5 | B10: =HYPERLINK("#RTM_CROSSWALK!A1","RTM_CROSSWALK") | C10: Check OFFER↔RTM linkage. | D10: Use relation type to separate direct evidence from broad context.
A11: 6 | B11: =HYPERLINK("#QUALITY_CHECKS!A1","QUALITY_CHECKS") | C11: Monitor workbook health. | D11: Check counts, TBDs, missing sources and flags before sharing.
A12: 7 | B12: =HYPERLINK("#DMAIC_AUDIT!A1","DMAIC_AUDIT") | C12: See what changed and why. | D12: Use as change log and governance record.
A13: 8 | B13: =HYPERLINK("#CODING_HANDOVER!A1","CODING_HANDOVER") | C13: Reproduction instructions. | D13: Copy to coding agent for deterministic rebuild.
A14: 9 | B14: =HYPERLINK("#RTM_RANKING!A1","RTM_RANKING") | C14: Audit RTM-only static importance (722 requirements, identical weights, no OFFER data). | D14: Cross-check against OFFER_RANKING and RTM_CROSSWALK for consistency.
A15: 10 | B15: =HYPERLINK("#RTM_LOOKUP!A1","RTM_LOOKUP") | C15: Look up any single RTM by ID and see every field for it in one place, incl. its OFFER cross-links and (if in the priority queue) its disposition. | D15: Fastest way to answer 'what does RTM-### actually require and what counts as evidence?' during a review meeting.
A16: 11 | B16: =HYPERLINK("#DASHBOARD_2!A1","DASHBOARD_2") | C16: Pick a Domain and/or Cluster and see live counts (total, by tier, average Weighted S) for that slice. | D16: Use before assigning review workload -- see which slice is biggest before diving into row-level detail.
A17: 12 | B17: =HYPERLINK("#CLUSTERS!A1","CLUSTERS") | C17: Reference: which of the 50 OFFER items sit in each of the 8 thematic clusters (C1-C8). Filter aid only -- not a ranking. | D17: Cross-check with DASHBOARD_2's Cluster picker.
A18: 13 | B18: =HYPERLINK("#TAXONOMY!A1","TAXONOMY") | C18: Reference: Requirement Type (SYSTEM/PROJECT/SAFETY) definitions, lifecycle supergroups, and the OFFER disposition vocabulary. | D18: Read once before using the Type/Category columns or the Disposition column.
A19: BT win % Human-readable head-to-head reading of the same ranking: 100 × (wins + 0.5 × ties) / (N − 1) against every other item on the list -- same order as Weighted S, just expressed as a win rate instead of a 0-100 score. Use win % when briefing a non-technical audience; use Weighted S when you need to defend a specific number.
A23: Negotiation flag | B23: Per-bidder issue marker: negotiation, RFI, not available, clarification. | C23: Drives agenda and follow-up.
A26: Control principle: OFFER ranking is static/cold and bidder-independent. Evaluation status, depth, source location and negotiation flags are live review inputs. Do not change the weighting or 0–3 classifications during a live evaluation round unless the panel formally approves a controlled rerun.
A33: Note: EVALUATION_INPUT is retained as the previous interaction sheet for traceability. Use EVALUATION_WORKSPACE as the current main interaction sheet because it adds per-bidder comments, review indices, board topics and closure notes.
A39: How to read the colour on this page (and where the other legends live)
B40: Pale green box | C40: Supporting definition / explanation -- background you don't need to act on, just understand.
B41: Pale yellow box | C41: Operational note or caution -- something to actually do or watch for (e.g. which sheet to use).
B42: Pale blue box | C42: Cross-reference / pointer to another sheet.
A44: This page's colours are the ONLY workbook-wide, decorative kind. Everywhere else, colour carries specific meaning and has its own dedicated legend, not repeated here: STATUS colours (pink/orange/green review flags) -> COMPLIANCE_LEGEND. Weight-dimension colours (L/R/P/F/Q/LC/C headers + row heatmaps) -> WEIGHTS_METHOD. Sheet-tab colours (which of the 6 groups a tab belongs to) -> NAVIGATION_MAP or README. Cluster colours (C1-C8) -> CLUSTERS. RTM_CROSSWALK relation-type colours (Direct/Supporting/Broad/Contextual) -> the note on that sheet itself.

Sheet DASHBOARD
A1: OFFER BT dashboard | N1: Auditable chart source data
A2: Embedded plots are linked to auditable source data at the right.
A3: =HYPERLINK("#START_HERE!A1","Start") | B3: =HYPERLINK("#DASHBOARD!A1","Dashboard") | C3: =HYPERLINK("#OFFER_RANKING!A1","Ranking") | D3: =HYPERLINK("#EVALUATION_INPUT!A1","Evaluate") | E3: =HYPERLINK("#OFFER_CANONICAL!A1","Canonical") | F3: =HYPERLINK("#RTM_CROSSWALK!A1","Crosswalk") | G3: =HYPERLINK("#WEIGHTS_METHOD!A1","Method") | N3: Offer | O3: Weighted S | Q3: Tier | R3: Count | T3: Category | U3: Count | V3: Average S | X3: Rank | Y3: Weighted S | Z3: BT λ
N4: OFFER-02 | O4: 54 | Q4: T0 Gate | R4: 6 | T4: Compliance / Quality | U4: 6 | V4: 37.444 | X4: 1 | Y4: 54 | Z4: 100
A5: OFFER items 50 Canonical OFFER-01…50 | D5: Gate items 6 Admissibility precedence | G5: Primary items 10 Top non-gate band | J5: Mean Weighted S 28.9 Frozen composite | N5: OFFER-48 | O5: 42.667 | Q5: T1 Primary | R5: 10 | T5: Reliability / RAM / Service | U5: 8 | V5: 33.833 | X5: 2 | Y5: 42.667 | Z5: 79.437
N6: OFFER-01 | O6: 32 | Q6: T2 Secondary | R6: 16 | T6: Controls / Software / Management | U6: 10 | V6: 30.067 | X6: 3 | Y6: 32 | Z6: 48.911
N7: OFFER-03 | O7: 32 | Q7: T3 Contextual | R7: 18 | T7: Performance / Process / Utilities | U7: 15 | V7: 27.933 | X7: 4 | Y7: 32 | Z7: 48.911
N8: OFFER-47 | O8: 32 | T8: Configuration / Layout / Support | U8: 11 | V8: 20.848 | X8: 5 | Y8: 32 | Z8: 48.911
N9: OFFER-49 | O9: 32 | X9: 6 | Y9: 32 | Z9: 48.911
N10: OFFER-09 | O10: 55.667 | X10: 7 | Y10: 55.667 | Z10: 32.555
N11: OFFER-42 | O11: 46.333 | X11: 8 | Y11: 46.333 | Z11: 28.053
N12: OFFER-20 | O12: 46 | X12: 9 | Y12: 46 | Z12: 22.688
N13: OFFER-34 | O13: 46 | X13: 10 | Y13: 46 | Z13: 22.688
N14: OFFER-29 | O14: 45 | X14: 11 | Y14: 45 | Z14: 18.544
N15: OFFER-04 | O15: 44 | X15: 12 | Y15: 44 | Z15: 15.285
N16: OFFER-05 | O16: 44 | X16: 13 | Y16: 44 | Z16: 15.285
N17: OFFER-27 | O17: 41.333 | X17: 14 | Y17: 41.333 | Z17: 12.684
N18: OFFER-33 | O18: 38.667 | X18: 15 | Y18: 38.667 | Z18: 10.584
X19: 16 | Y19: 38.667 | Z19: 10.584
X20: 17 | Y20: 36 | Z20: 8.369
X21: 18 | Y21: 36 | Z21: 8.369
X22: 19 | Y22: 35.667 | Z22: 7.046
X23: 20 | Y23: 32.667 | Z23: 5.946
X24: 21 | Y24: 32.667 | Z24: 5.946
X25: 22 | Y25: 32 | Z25: 4.756
X26: 23 | Y26: 32 | Z26: 4.756
X27: 24 | Y27: 31.667 | Z27: 4.028
X28: 25 | Y28: 29.333 | Z28: 3.607
X29: 26 | Y29: 26.667 | Z29: 3.23
X30: 27 | Y30: 24 | Z30: 2.193
... X50: 47 | Y50: 14.333 | Z50: 0.219
A51: BT MLE converged in 301 iterations (final relative change 9.51E-11). This convergence confirms numerical stability; it does not create new engineering judgement. | X51: 48 | Y51: 12 | Z51: 0.181
X52: 49 | Y52: 10.667 | Z52: 0.147
X53: 50 | Y53: 6.333 | Z53: 0.117
A56: Why does the Weighted S line spike at item 7, above item 1? Ranks 1-6 are the six T0 Gate items -- pinned to the TOP of the official rank by gate precedence, regardless of their own S score (54 / 42.7 / 32 / 32 / 32 / 32 -- all comparatively low). Rank 7 is the first non-gated item, OFFER-09 "LN2 Techno-Economic Evaluation (CAPEX/OPEX)" (T1 Primary), and it holds the single highest Weighted S of all 50 OFFER items: 55.67 -- higher even than the #1-ranked gate item. So the S-line dips through the low-S gate items, then jumps sharply upward exactly where the top-value item finally appears. This is expected behaviour, not a data error: gate items must rank first by policy (pass/fail compliance), independent of how much technical/value weight they carry -- see WEIGHTS_METHOD for the gate-precedence rule.

Sheet DASHBOARD_2
A1: Filter view — by Domain or Cluster
A2: Pick a Domain and/or a Cluster below; the counts update live. This is a filter aid over the same 722 RTMs in RTM_RANKING -- for row-level detail, use RTM_RANKING's own AutoFilter after picking your slice here, or open RTM_LOOKUP for one specific RTM.
A3: =HYPERLINK("#START_HERE!A1","Start") | B3: =HYPERLINK("#DASHBOARD!A1","Dashboard") | C3: =HYPERLINK("#RTM_LOOKUP!A1","RTM Lookup") | D3: =HYPERLINK("#DASHBOARD_2!A1","Filter view") | E3: =HYPERLINK("#RTM_REVIEW_QUEUE!A1","Queue") | F3: =HYPERLINK("#RTM_RANKING!A1","Ranking") | G3: =HYPERLINK("#DOMAIN_SUMMARY!A1","Domains") | H3: =HYPERLINK("#CLUSTERS!A1","Clusters") | I3: =HYPERLINK("#TAXONOMY!A1","Taxonomy")
A5: Domain | B5: (ALL) | C5: Domain criteria (helper): | D5: =IF(B5="(ALL)","*",B5)
A6: Cluster | B6: (ALL) | C6: Cluster criteria (helper): | D6: =IF(B6="(ALL)","*","*"&B6&" —*")
A8: Live counts for this slice
A9: Matching RTMs | B9: =COUNTIFS(RTM_RANKING!$E$6:$E$728,$D$5,RTM_RANKING!$I$6:$I$728,$D$6)
A10: of which T0 Gate | B10: =COUNTIFS(RTM_RANKING!$E$6:$E$728,$D$5,RTM_RANKING!$I$6:$I$728,$D$6,RTM_RANKING!$D$6:$D$728,"T0 Gate")
A11: of which T1 Primary | B11: =COUNTIFS(RTM_RANKING!$E$6:$E$728,$D$5,RTM_RANKING!$I$6:$I$728,$D$6,RTM_RANKING!$D$6:$D$728,"T1 Primary")
A12: of which T2 Secondary | B12: =COUNTIFS(RTM_RANKING!$E$6:$E$728,$D$5,RTM_RANKING!$I$6:$I$728,$D$6,RTM_RANKING!$D$6:$D$728,"T2 Secondary")
A13: of which T3 Contextual | B13: =COUNTIFS(RTM_RANKING!$E$6:$E$728,$D$5,RTM_RANKING!$I$6:$I$728,$D$6,RTM_RANKING!$D$6:$D$728,"T3 Contextual")
A14: Average Weighted S | B14: =IFERROR(ROUND(AVERAGEIFS(RTM_RANKING!$V$6:$V$728,RTM_RANKING!$E$6:$E$728,$D$5,RTM_RANKING!$I$6:$I$728,$D$6),2),"n/a")
A16: RTM-side charts (mirrors DASHBOARD's OFFER-side charts) + crosswalk coverage
A17: Chart data below is auto-computed (COUNTIF/COUNTIFS off RTM_RANKING) -- not for manual editing.
A18: Tier | B18: RTM count | D18: Coverage | E18: RTM count
A19: T0 Gate | B19: =COUNTIF(RTM_RANKING!$D$6:$D$727,"T0 Gate") | D19: Linked | E19: =COUNTIFS(RTM_RANKING!$AG$6:$AG$727,"<>Not linked to an OFFER item",RTM_RANKING!$AG$6:$AG$727,"<>")
A20: T1 Primary | B20: =COUNTIF(RTM_RANKING!$D$6:$D$727,"T1 Primary") | D20: Not linked | E20: =COUNTIF(RTM_RANKING!$AG$6:$AG$727,"Not linked to an OFFER item")
A21: T2 Secondary | B21: =COUNTIF(RTM_RANKING!$D$6:$D$727,"T2 Secondary")
A22: T3 Contextual | B22: =COUNTIF(RTM_RANKING!$D$6:$D$727,"T3 Contextual") | D22: Tier | E22: Linked | F22: Not linked
D23: T0 Gate | E23: =COUNTIFS(RTM_RANKING!$D$6:$D$727,"T0 Gate",RTM_RANKING!$AG$6:$AG$727,"<>Not linked to an OFFER item",RTM_RANKING!$AG$6:$AG$727,"<>") | F23: =COUNTIFS(RTM_RANKING!$D$6:$D$727,"T0 Gate",RTM_RANKING!$AG$6:$AG$727,"Not linked to an OFFER item")
D24: T1 Primary | E24: =COUNTIFS(RTM_RANKING!$D$6:$D$727,"T1 Primary",RTM_RANKING!$AG$6:$AG$727,"<>Not linked to an OFFER item",RTM_RANKING!$AG$6:$AG$727,"<>") | F24: =COUNTIFS(RTM_RANKING!$D$6:$D$727,"T1 Primary",RTM_RANKING!$AG$6:$AG$727,"Not linked to an OFFER item")
D25: T2 Secondary | E25: =COUNTIFS(RTM_RANKING!$D$6:$D$727,"T2 Secondary",RTM_RANKING!$AG$6:$AG$727,"<>Not linked to an OFFER item",RTM_RANKING!$AG$6:$AG$727,"<>") | F25: =COUNTIFS(RTM_RANKING!$D$6:$D$727,"T2 Secondary",RTM_RANKING!$AG$6:$AG$727,"Not linked to an OFFER item")
D26: T3 Contextual | E26: =COUNTIFS(RTM_RANKING!$D$6:$D$727,"T3 Contextual",RTM_RANKING!$AG$6:$AG$727,"<>Not linked to an OFFER item",RTM_RANKING!$AG$6:$AG$727,"<>") | F26: =COUNTIFS(RTM_RANKING!$D$6:$D$727,"T3 Contextual",RTM_RANKING!$AG$6:$AG$727,"Not linked to an OFFER item")
A28: Coverage read: 293 of 722 RTMs (41%) have a direct RTM_CROSSWALK link to at least one OFFER item; 429 (59%) do not. That is expected, not a defect -- OFFER items are the bidder's own response document, so many RTMs (procedural/administrative requirements, or ones no OFFER section happens to address in prose) will never get a direct textual link even in a fully compliant bid. The number worth watching is the T0 Gate row below: 21 of 43 T0 Gate RTMs (49%) have NO direct OFFER link -- for a Gate requirement specifically, that means compliance for that item is resting on EVALUATION_WORKSPACE's manual review, not on a traceable OFFER-text citation. Worth a reviewer pass on just those 21 before sign-off, not a workbook defect to fix.
A95: Review-completion rollup (RTM_REVIEW_QUEUE)
A96: 0 of 289 priority-queue RTMs (0%) have a Disposition recorded (anything other than blank/TBD); 289 (100%) are still awaiting a reviewer decision. This is the single project-level 'how far along is this evaluation' number the per-item STATUS/Disposition fields never rolled up into one place before -- same pattern as the crosswalk-coverage callout above, applied to review completion instead of RTM<->OFFER linkage. Re-run build_workbook_v20.py's Section 7 (or a future refresh) any time RTM_REVIEW_QUEUE!Disposition values change, to keep this number current -- it is a snapshot, not a live formula, so it can drift if the workbook is edited without a rebuild.

Sheet RTM_LOOKUP
A1: RTM Lookup — enter any RTM ID
A2: Type an RTM ID (e.g. RTM-693) in the yellow box. Every field for that requirement pulls in below, across all 722 canonical RTMs -- not just the 289 in the priority queue.
A3: =HYPERLINK("#START_HERE!A1","Start") | B3: =HYPERLINK("#DASHBOARD!A1","Dashboard") | C3: =HYPERLINK("#RTM_LOOKUP!A1","RTM Lookup") | D3: =HYPERLINK("#DASHBOARD_2!A1","Filter view") | E3: =HYPERLINK("#RTM_REVIEW_QUEUE!A1","Queue") | F3: =HYPERLINK("#RTM_RANKING!A1","Ranking") | G3: =HYPERLINK("#DOMAIN_SUMMARY!A1","Domains") | H3: =HYPERLINK("#CLUSTERS!A1","Clusters") | I3: =HYPERLINK("#TAXONOMY!A1","Taxonomy")
A5: RTM ID: | B5: RTM-693 | C5: Format: RTM-### (3 digits, e.g. RTM-001, RTM-693). If the box below shows #N/A, check the ID exists on RTM_RANKING.
A7: Field | B7: Value
A8: Rank (of 722) | B8: =IFERROR(INDEX(RTM_RANKING!$A$6:$A$728,MATCH($B$5,RTM_RANKING!$B$6:$B$728,0)),"— RTM ID not found —")
A9: Gate (T0?) | B9: =IFERROR(INDEX(RTM_RANKING!$C$6:$C$728,MATCH($B$5,RTM_RANKING!$B$6:$B$728,0)),"— RTM ID not found —")
A10: Tier | B10: =IFERROR(INDEX(RTM_RANKING!$D$6:$D$728,MATCH($B$5,RTM_RANKING!$B$6:$B$728,0)),"— RTM ID not found —")
A11: Domain | B11: =IFERROR(INDEX(RTM_RANKING!$E$6:$E$728,MATCH($B$5,RTM_RANKING!$B$6:$B$728,0)),"— RTM ID not found —")
A12: Requirement Type | B12: =IFERROR(INDEX(RTM_RANKING!$F$6:$F$728,MATCH($B$5,RTM_RANKING!$B$6:$B$728,0)),"— RTM ID not found —")
A13: Category | B13: =IFERROR(INDEX(RTM_RANKING!$G$6:$G$728,MATCH($B$5,RTM_RANKING!$B$6:$B$728,0)),"— RTM ID not found —")
A14: Subcategory | B14: =IFERROR(INDEX(RTM_RANKING!$H$6:$H$728,MATCH($B$5,RTM_RANKING!$B$6:$B$728,0)),"— RTM ID not found —")
A15: Cluster | B15: =IFERROR(INDEX(RTM_RANKING!$I$6:$I$728,MATCH($B$5,RTM_RANKING!$B$6:$B$728,0)),"— RTM ID not found —")
A16: PDF page | B16: =IFERROR(INDEX(RTM_RANKING!$J$6:$J$728,MATCH($B$5,RTM_RANKING!$B$6:$B$728,0)),"— RTM ID not found —")
A17: Section | B17: =IFERROR(INDEX(RTM_RANKING!$K$6:$K$728,MATCH($B$5,RTM_RANKING!$B$6:$B$728,0)),"— RTM ID not found —")
A18: Section title | B18: =IFERROR(INDEX(RTM_RANKING!$L$6:$L$728,MATCH($B$5,RTM_RANKING!$B$6:$B$728,0)),"— RTM ID not found —")
A19: Shall statement | B19: =IFERROR(INDEX(RTM_RANKING!$M$6:$M$728,MATCH($B$5,RTM_RANKING!$B$6:$B$728,0)),"— RTM ID not found —")
A20: Full verbatim requirement | B20: =IFERROR(INDEX(RTM_RANKING!$N$6:$N$728,MATCH($B$5,RTM_RANKING!$B$6:$B$728,0)),"— RTM ID not found —")
A21: Weighted S | B21: =IFERROR(INDEX(RTM_RANKING!$V$6:$V$728,MATCH($B$5,RTM_RANKING!$B$6:$B$728,0)),"— RTM ID not found —")
A22: BT Win % | B22: =IFERROR(INDEX(RTM_RANKING!$W$6:$W$728,MATCH($B$5,RTM_RANKING!$B$6:$B$728,0)),"— RTM ID not found —")
A23: Primary dimension | B23: =IFERROR(INDEX(RTM_RANKING!$Y$6:$Y$728,MATCH($B$5,RTM_RANKING!$B$6:$B$728,0)),"— RTM ID not found —")
A24: Actual explicit code / standard | B24: =IFERROR(INDEX(RTM_RANKING!$AA$6:$AA$728,MATCH($B$5,RTM_RANKING!$B$6:$B$728,0)),"— RTM ID not found —")
A25: Evidence / measurability | B25: =IFERROR(INDEX(RTM_RANKING!$AC$6:$AC$728,MATCH($B$5,RTM_RANKING!$B$6:$B$728,0)),"— RTM ID not found —")
A26: Explicit deliverable / proof | B26: =IFERROR(INDEX(RTM_RANKING!$AD$6:$AD$728,MATCH($B$5,RTM_RANKING!$B$6:$B$728,0)),"— RTM ID not found —")
A27: Applicable phase(s) | B27: =IFERROR(INDEX(RTM_RANKING!$AE$6:$AE$728,MATCH($B$5,RTM_RANKING!$B$6:$B$728,0)),"— RTM ID not found —")
A28: Evidence basis / review | B28: =IFERROR(INDEX(RTM_RANKING!$AF$6:$AF$728,MATCH($B$5,RTM_RANKING!$B$6:$B$728,0)),"— RTM ID not found —")
A29: Linked OFFER items (crosswalk) | B29: =IFERROR(INDEX(RTM_RANKING!$AG$6:$AG$728,MATCH($B$5,RTM_RANKING!$B$6:$B$728,0)),"— RTM ID not found —")
A30: Note: if the verbatim text above still looks cut off (a handful of items run to 25+ bullets), the full text is always in RTM_RANKING!N for this RTM ID, or widen row 20 further.
A31: Reviewer disposition for this RTM (from RTM_REVIEW_QUEUE, if it's in the priority subset)
A32: Disposition | B32: =IFERROR(INDEX(RTM_REVIEW_QUEUE!$U$6:$U$294,MATCH($B$5,RTM_REVIEW_QUEUE!$B$6:$B$294,0)),"— not in the priority queue —")
A33: Comments | B33: =IFERROR(INDEX(RTM_REVIEW_QUEUE!$V$6:$V$294,MATCH($B$5,RTM_REVIEW_QUEUE!$B$6:$B$294,0)),"— not in the priority queue —")
A34: Cross-link / check to perform | B34: =IFERROR(INDEX(RTM_REVIEW_QUEUE!$W$6:$W$294,MATCH($B$5,RTM_REVIEW_QUEUE!$B$6:$B$294,0)),"— not in the priority queue —")

Sheet COMPLIANCE_LEGEND
A1: Compliance status legend
A2: Dropdown conventions used in EVALUATION_INPUT.
A3: =HYPERLINK("#START_HERE!A1","Start") | B3: =HYPERLINK("#DASHBOARD!A1","Dashboard") | C3: =HYPERLINK("#OFFER_RANKING!A1","Ranking") | D3: =HYPERLINK("#EVALUATION_INPUT!A1","Evaluate") | E3: =HYPERLINK("#OFFER_CANONICAL!A1","Canonical") | F3: =HYPERLINK("#RTM_CROSSWALK!A1","Crosswalk") | G3: =HYPERLINK("#WEIGHTS_METHOD!A1","Method")
A5: Status | B5: Definition | C5: Example | D5: Deviation | E5: Next steps | F5: Who resolves
A6: OK | B6: Fulfills requirements | C6: Requested: 100, Provided: 500 | D6: +400 (overperformance) | E6: Nothing
A7: OK/Minor | B7: Either OK or minor; evaluated as very low risk and can be closed | E7: Nothing
A8: NOK | B8: Does not fulfill requirements | C8: Requested: 4, Provided: 3 | D8: -1 (25% shortfall) | E8: Decide whether to enforce or relax original requirement
A9: MISS | B9: Required information missing | C9: No mention about it | D9: Unknown | E9: Follow-up needed
A10: Minor disc. | B10: Does not fully fulfill requirements, but can be resolved during contract performance | E10: Likely solvable without management intervention | F10: ACR level
A11: Major disc. | B11: Seems like a NOK but can be resolved during contract performance | E11: Likely solvable with management intervention | F11: Management level
A12: ERROR | B12: Misinterpretation of requirement | C12: Response does not match intent | D12: Major error | E12: Clarify with supplier
A13: TBD | B13: Not yet evaluated (default state) | E13: Evaluate
A16: How to read the colours in this workbook
A17: STATUS (this table, above) | B17: Green/pink/orange/purple/yellow, per-value as shown above. | D17: EVALUATION_WORKSPACE!Q6:Q55, W6:W55 (live, driven by the dropdown) · QUALITY_CHECKS!D6:D17 (health-check OK/CHECK/OPEN)
A18: Tier (T0 Gate / T1 / T2 / T3) | B18: Pale red / orange / yellow / green -- a SEPARATE colour system from STATUS, do not read them against each other. | D18: EVALUATION_WORKSPACE!B6:B55 and every Tier column on RTM_RANKING, OFFER_RANKING, RTM_REVIEW_QUEUE
A19: Cluster (C1-C8) | B19: New (Phase 9): soft blue/teal/lavender/mauve/tan tones, one per cluster, deliberately kept out of the STATUS and Tier hue families so none of the three systems gets misread against another. | D19: CLUSTERS!A6:A13 (exact) · RTM_RANKING!I6:I727 and RTM_REVIEW_QUEUE!G6:G294 (conditional, matches the cluster id inside the longer cell text, incl. "Inferred:" rows)
A20: Soft cream fill = safe to type/select here | B20: New (Phase 9): manual-entry cells that had no visual cue before a value was entered now carry a light cream base fill, so the invitation to edit is visible up front, not just after a STATUS is picked. White/no-fill cells elsewhere are formulas or reference text -- not meant to be edited directly. | D20: EVALUATION_WORKSPACE!R,S,U,X,Y,AA,AD,AE,AF (rows 6-55). v20: extended to RTM_REVIEW_QUEUE!Comments and NEGOTIATION_AGENDA!Reviewer Comment, plus a new Comment column added to QUALITY_CHECKS (previously had none). DMAIC_AUDIT/AUDIT_NOTES deliberately left as-is -- both are structured audit logs, not live reviewer-input sheets.
A21: Technical Depth (A_/B_, EVALUATION_WORKSPACE!R,X) | B21: Soft pink=0.4 declarative / soft orange=0.7 partial / soft green=1.0 fully substantiated -- same weak->strong direction as STATUS's pink/orange/green, deliberately paler so it doesn't read as an actual STATUS value next to the STATUS column beside it.
A23: Primary vs. Supporting RTM, and Review flag -- formal definitions
A24: Both fields are hand-curated per OFFER item (OFFER_CANONICAL!primary_rtm_ids / supporting_context_rtm_ids / review_flag), not formula- or rule-derived -- no code branch assigns either. Documented here per GBO's explicit request so this is captured rather than left inferred.
A26: Field | B26: Definition | C26: Example
A27: Primary RTM(s) | B27: The RTM(s) that an OFFER item's response text is actually, centrally answering -- the requirement(s) the offer was written to address. | C27: OFFER-01's primary RTM is RTM-001 (the general-responsibility clause its text directly confirms).
A28: Supporting RTM(s) | B28: RTMs in the same contract section as the OFFER item that get pulled in as context, but are not what the offer text is centrally about -- background/section-mates, not the primary evidence basis. | C28: Section-mates of RTM-001 under §4.13 that are relevant context but not individually answered.
A29: Review flag | B29: Reviewer note on whether the Primary/Supporting split (or the crosswalk coverage generally) needs a second look before being trusted as-is. Standardised (v20) to 5 controlled values -- see the review_flag dropdown on OFFER_CANONICAL/EVALUATION_WORKSPACE/OFFER_RANKING for the live list and colours. | C29: "Review — breadth" = the OFFER text plausibly covers more RTMs than the direct link captures.

Sheet EVALUATION_WORKSPACE
A1: Evaluation workspace — 2 bidders, evidence first
A2: Main interaction sheet. The static rank is read-only; reviewer input starts at the STATUS columns for Bidder A and Bidder B.
A3: =HYPERLINK("#START_HERE!A1","Start") | B3: =HYPERLINK("#DASHBOARD!A1","Dashboard") | C3: =HYPERLINK("#EVALUATION_WORKSPACE!A1","Workspace") | D3: =HYPERLINK("#NEGOTIATION_AGENDA!A1","Agenda") | E3: =HYPERLINK("#OFFER_RANKING!A1","Ranking") | F3: =HYPERLINK("#RTM_CROSSWALK!A1","Crosswalk") | G3: =HYPERLINK("#QUALITY_CHECKS!A1","Quality") | H3: =HYPERLINK("#DMAIC_AUDIT!A1","DMAIC") | I3: =HYPERLINK("#CODING_HANDOVER!A1","Handover")
AC4: Formula-driven -- fills itself in once A_STATUS/B_STATUS are set; nothing fabricated while both are TBD.
A5: Rank | B5: Tier | C5: OFFER ID | D5: Title | E5: Section | F5: Category | G5: Primary Dim | H5: Weighted S | I5: BT Win % | J5: Gate | K5: Evidence / measurability | L5: Explicit deliverable / proof | M5: Applicable phase(s) | N5: Primary RTMs | O5: Supporting RTMs | P5: Review flag | Q5: A_STATUS | R5: A_Technical Depth | S5: A_Source / Location | T5: A_Negotiation | U5: A_Reviewer Comment | V5: A_Review Index | W5: B_STATUS | X5: B_Technical Depth | Y5: B_Source / Location | Z5: B_Negotiation | AA5: B_Reviewer Comment | AB5: B_Review Index | AC5: Z_comment (auto A vs B synthesis) | AD5: Board / Negotiation Topic | AE5: Owner | AF5: Closure / Decision Note
A6: 1 | B6: T0 Gate | C6: OFFER-02 | D6: Assumptions, Deviations & Additions Register | E6: §4.1 | F6: Compliance / Quality | G6: Reliability | H6: 54 | I6: 100 | J6: Yes | K6: Submit and review the named deliverable with RTM traceability and approval status; RAM/maintenance substantiation and recovery/failure-response evidence; Document review, inspection, certification, audit or traceable QC record | L6: Offer response: Assumptions, Deviations & Additions Register | M6: L0 Tender / Offer; L1 Conceptual Design; L2 Detailed Design | N6: RTM-004 | O6: RTM-001..RTM-003 | P6: OK | Q6: TBD | V6: =IF(Q6="TBD","",H6*R6*IF(Q6="OK",1,IF(Q6="OK/Minor",0.85,IF(Q6="Minor disc.",0.7,IF(Q6="Major disc.",0.45,IF(Q6="MISS",0.25,0)))))) | W6: TBD | AB6: =IF(W6="TBD","",H6*X6*IF(W6="OK",1,IF(W6="OK/Minor",0.85,IF(W6="Minor disc.",0.7,IF(W6="Major disc.",0.45,IF(W6="MISS",0.25,0)))))) | AC6: =IF(AND(Q6="TBD",W6="TBD"),"Not yet evaluated — awaiting bidder review.",IF(Q6="TBD",CONCATENATE("Bidder B: ",W6," — ",IF(AA6="","(no comment)",AA6)," | Bidder A not yet evaluated."),IF(W6="TBD",CONCATENATE("Bidder A: ",Q6," — ",IF(U6="","(no comment)",U6)," | Bidder B not yet evaluated."),CONCATENATE("Bidder A: ",Q6," — ",IF(U6="","(no comment)",U6)," || Bidder B: ",W6," — ",IF(AA6="","(no comment)",AA6)," | ",IF(Q6=W6,"Comparable disposition.","Diverging disposition — flag for negotiation.")))))
A7: 2 | B7: T0 Gate | C7: OFFER-48 | D7: Detailed Quality Control Procedures | E7: §8.1.3.1 | F7: Compliance / Quality | G7: Safety / Legal | H7: 42.6667 | I7: 97.9592 | J7: Yes | K7: Submit and review the named deliverable with RTM traceability and approval status; Document review, inspection, certification, audit or traceable QC record; Conformity/safety assessment, certification and approved safety evidence | L7: Offer response: Detailed Quality Control Procedures; Quality Assurance Plan (QAP) | M7: L0 Tender / Offer; L1 Conceptual Design; L2 Detailed Design; L3 Procurement & Manufacturing / FAT; L4 Installation; L5 Standalone Commissioning; L6 Site Acceptance Testing | N7: RTM-650..RTM-652 | P7: OK | Q7: TBD | V7: =IF(Q7="TBD","",H7*R7*IF(Q7="OK",1,IF(Q7="OK/Minor",0.85,IF(Q7="Minor disc.",0.7,IF(Q7="Major disc.",0.45,IF(Q7="MISS",0.25,0)))))) | W7: TBD | AB7: =IF(W7="TBD","",H7*X7*IF(W7="OK",1,IF(W7="OK/Minor",0.85,IF(W7="Minor disc.",0.7,IF(W7="Major disc.",0.45,IF(W7="MISS",0.25,0)))))) | AC7: =IF(AND(Q7="TBD",W7="TBD"),"Not yet evaluated — awaiting bidder review.",IF(Q7="TBD",CONCATENATE("Bidder B: ",W7," — ",IF(AA7="","(no comment)",AA7)," | Bidder A not yet evaluated."),IF(W7="TBD",CONCATENATE("Bidder A: ",Q7," — ",IF(U7="","(no comment)",U7)," | Bidder B not yet evaluated."),CONCATENATE("Bidder A: ",Q7," — ",IF(U7="","(no comment)",U7)," || Bidder B: ",W7," — ",IF(AA7="","(no comment)",AA7)," | ",IF(Q7=W7,"Comparable disposition.","Diverging disposition — flag for negotiation.")))))
A8: 3 | B8: T0 Gate | C8: OFFER-01 | D8: Tender Compliance Confirmation | E8: §4.1 | F8: Compliance / Quality | G8: Safety / Legal | H8: 32 | I8: 92.8571 | J8: Yes | K8: Submit and review the named deliverable with RTM traceability and approval status; Document review, inspection, certification, audit or traceable QC record; Conformity/safety assessment, certification and approved safety evidence | L8: Offer response: Tender Compliance Confirmation | M8: L0 Tender / Offer; L1 Conceptual Design; L2 Detailed Design | N8: RTM-001; RTM-003 | O8: RTM-002; RTM-004 | P8: OK | Q8: TBD | V8: =IF(Q8="TBD","",H8*R8*IF(Q8="OK",1,IF(Q8="OK/Minor",0.85,IF(Q8="Minor disc.",0.7,IF(Q8="Major disc.",0.45,IF(Q8="MISS",0.25,0)))))) | W8: TBD | AB8: =IF(W8="TBD","",H8*X8*IF(W8="OK",1,IF(W8="OK/Minor",0.85,IF(W8="Minor disc.",0.7,IF(W8="Major disc.",0.45,IF(W8="MISS",0.25,0)))))) | AC8: =IF(AND(Q8="TBD",W8="TBD"),"Not yet evaluated — awaiting bidder review.",IF(Q8="TBD",CONCATENATE("Bidder B: ",W8," — ",IF(AA8="","(no comment)",AA8)," | Bidder A not yet evaluated."),IF(W8="TBD",CONCATENATE("Bidder A: ",Q8," — ",IF(U8="","(no comment)",U8)," | Bidder B not yet evaluated."),CONCATENATE("Bidder A: ",Q8," — ",IF(U8="","(no comment)",U8)," || Bidder B: ",W8," — ",IF(AA8="","(no comment)",AA8)," | ",IF(Q8=W8,"Comparable disposition.","Diverging disposition — flag for negotiation.")))))
A9: 4 | B9: T0 Gate | C9: OFFER-03 | D9: Integrated Technical Proposal & Execution Strategy | E9: §4.1 | F9: Compliance / Quality | G9: Safety / Legal | H9: 32 | I9: 92.8571 | J9: Yes | K9: Submit and review the named deliverable with RTM traceability and approval status; Document review, inspection, certification, audit or traceable QC record; Conformity/safety assessment, certification and approved safety evidence | L9: Offer response: Integrated Technical Proposal & Execution Strategy | M9: L0 Tender / Offer; L1 Conceptual Design; L2 Detailed Design | N9: RTM-002 | O9: RTM-001; RTM-003..RTM-004 | P9: OK | Q9: TBD | V9: =IF(Q9="TBD","",H9*R9*IF(Q9="OK",1,IF(Q9="OK/Minor",0.85,IF(Q9="Minor disc.",0.7,IF(Q9="Major disc.",0.45,IF(Q9="MISS",0.25,0)))))) | W9: TBD | AB9: =IF(W9="TBD","",H9*X9*IF(W9="OK",1,IF(W9="OK/Minor",0.85,IF(W9="Minor disc.",0.7,IF(W9="Major disc.",0.45,IF(W9="MISS",0.25,0)))))) | AC9: =IF(AND(Q9="TBD",W9="TBD"),"Not yet evaluated — awaiting bidder review.",IF(Q9="TBD",CONCATENATE("Bidder B: ",W9," — ",IF(AA9="","(no comment)",AA9)," | Bidder A not yet evaluated."),IF(W9="TBD",CONCATENATE("Bidder A: ",Q9," — ",IF(U9="","(no comment)",U9)," | Bidder B not yet evaluated."),CONCATENATE("Bidder A: ",Q9," — ",IF(U9="","(no comment)",U9)," || Bidder B: ",W9," — ",IF(AA9="","(no comment)",AA9)," | ",IF(Q9=W9,"Comparable disposition.","Diverging disposition — flag for negotiation.")))))
A10: 5 | B10: T0 Gate | C10: OFFER-47 | D10: Quality Assurance Program (QAP) Definition | E10: §8 | F10: Compliance / Quality | G10: Safety / Legal | H10: 32 | I10: 92.8571 | J10: Yes | K10: Submit and review the named deliverable with RTM traceability and approval status; Document review, inspection, certification, audit or traceable QC record; Conformity/safety assessment, certification and approved safety evidence | L10: Offer response: Quality Assurance Program (QAP) Definition; Quality Assurance Plan (QAP) | M10: L0 Tender / Offer; L1 Conceptual Design; L2 Detailed Design; L3 Procurement & Manufacturing / FAT; L4 Installation; L5 Standalone Commissioning; L6 Site Acceptance Testing | N10: RTM-642 | O10: RTM-648..RTM-652 | P10: OK — Review breadth | Q10: TBD | V10: =IF(Q10="TBD","",H10*R10*IF(Q10="OK",1,IF(Q10="OK/Minor",0.85,IF(Q10="Minor disc.",0.7,IF(Q10="Major disc.",0.45,IF(Q10="MISS",0.25,0)))))) | W10: TBD | AB10: =IF(W10="TBD","",H10*X10*IF(W10="OK",1,IF(W10="OK/Minor",0.85,IF(W10="Minor disc.",0.7,IF(W10="Major disc.",0.45,IF(W10="MISS",0.25,0)))))) | AC10: =IF(AND(Q10="TBD",W10="TBD"),"Not yet evaluated — awaiting bidder review.",IF(Q10="TBD",CONCATENATE("Bidder B: ",W10," — ",IF(AA10="","(no comment)",AA10)," | Bidder A not yet evaluated."),IF(W10="TBD",CONCATENATE("Bidder A: ",Q10," — ",IF(U10="","(no comment)",U10)," | Bidder B not yet evaluated."),CONCATENATE("Bidder A: ",Q10," — ",IF(U10="","(no comment)",U10)," || Bidder B: ",W10," — ",IF(AA10="","(no comment)",AA10)," | ",IF(Q10=W10,"Comparable disposition.","Diverging disposition — flag for negotiation.")))))
A11: 6 | B11: T0 Gate | C11: OFFER-49 | D11: Codes, Standards & Compliance Framework | E11: §9 | F11: Compliance / Quality | G11: Safety / Legal | H11: 32 | I11: 92.8571 | J11: Yes | K11: Submit and review the named deliverable with RTM traceability and approval status; Witnessed FAT/SAT/commissioning test against stated acceptance criteria; Conformity/safety assessment, certification and approved safety evidence | L11: Offer response: Codes, Standards & Compliance Framework; List / register / matrix | M11: L0 Tender / Offer; L3 Procurement & Manufacturing / FAT; L1 Conceptual Design; L2 Detailed Design; L4 Installation; L5 Standalone Commissioning; L6 Site Acceptance Testing | N11: RTM-687..RTM-688 | O11: RTM-689..RTM-705 | P11: OK — Review breadth | Q11: TBD | V11: =IF(Q11="TBD","",H11*R11*IF(Q11="OK",1,IF(Q11="OK/Minor",0.85,IF(Q11="Minor disc.",0.7,IF(Q11="Major disc.",0.45,IF(Q11="MISS",0.25,0)))))) | W11: TBD | AB11: =IF(W11="TBD","",H11*X11*IF(W11="OK",1,IF(W11="OK/Minor",0.85,IF(W11="Minor disc.",0.7,IF(W11="Major disc.",0.45,IF(W11="MISS",0.25,0)))))) | AC11: =IF(AND(Q11="TBD",W11="TBD"),"Not yet evaluated — awaiting bidder review.",IF(Q11="TBD",CONCATENATE("Bidder B: ",W11," — ",IF(AA11="","(no comment)",AA11)," | Bidder A not yet evaluated."),IF(W11="TBD",CONCATENATE("Bidder A: ",Q11," — ",IF(U11="","(no comment)",U11)," | Bidder B not yet evaluated."),CONCATENATE("Bidder A: ",Q11," — ",IF(U11="","(no comment)",U11)," || Bidder B: ",W11," — ",IF(AA11="","(no comment)",AA11)," | ",IF(Q11=W11,"Comparable disposition.","Diverging disposition — flag for negotiation.")))))
A12: 7 | B12: T1 Primary | C12: OFFER-09 | D12: LN2 Techno-Economic Evaluation (CAPEX/OPEX) | E12: §4.2.5 | F12: Performance / Process / Utilities | G12: Reliability | H12: 55.6667 | I12: 87.7551 | J12: No | K12: Submit and review the named deliverable with RTM traceability and approval status; Calculation/model plus calibrated measurement or recorded trend; Functional design/configuration review and sequence/interface demonstration | L12: Offer response: LN2 Techno-Economic Evaluation (CAPEX/OPEX) | M12: L0 Tender / Offer; PAC / Handover; L1 Conceptual Design; L2 Detailed Design | O12: RTM-045..RTM-047 | P12: Review — accept context | Q12: TBD | V12: =IF(Q12="TBD","",H12*R12*IF(Q12="OK",1,IF(Q12="OK/Minor",0.85,IF(Q12="Minor disc.",0.7,IF(Q12="Major disc.",0.45,IF(Q12="MISS",0.25,0)))))) | W12: TBD | AB12: =IF(W12="TBD","",H12*X12*IF(W12="OK",1,IF(W12="OK/Minor",0.85,IF(W12="Minor disc.",0.7,IF(W12="Major disc.",0.45,IF(W12="MISS",0.25,0)))))) | AC12: =IF(AND(Q12="TBD",W12="TBD"),"Not yet evaluated — awaiting bidder review.",IF(Q12="TBD",CONCATENATE("Bidder B: ",W12," — ",IF(AA12="","(no comment)",AA12)," | Bidder A not yet evaluated."),IF(W12="TBD",CONCATENATE("Bidder A: ",Q12," — ",IF(U12="","(no comment)",U12)," | Bidder B not yet evaluated."),CONCATENATE("Bidder A: ",Q12," — ",IF(U12="","(no comment)",U12)," || Bidder B: ",W12," — ",IF(AA12="","(no comment)",AA12)," | ",IF(Q12=W12,"Comparable disposition.","Diverging disposition — flag for negotiation.")))))
A13: 8 | B13: T1 Primary | C13: OFFER-42 | D13: After-Sales Service Organization & Pricing | E13: §4.15 | F13: Reliability / RAM / Service | G13: Reliability | H13: 46.3333 | I13: 85.7143 | J13: No | K13: Submit and review the named deliverable with RTM traceability and approval status; Functional design/configuration review and sequence/interface demonstration; RAM/maintenance substantiation and recovery/failure-response evidence | L13: Offer response: After-Sales Service Organization & Pricing; Procedure / work instruction | M13: L0 Tender / Offer; L1 Conceptual Design; L2 Detailed Design | N13: RTM-563..RTM-565 | P13: OK | Q13: TBD | V13: =IF(Q13="TBD","",H13*R13*IF(Q13="OK",1,IF(Q13="OK/Minor",0.85,IF(Q13="Minor disc.",0.7,IF(Q13="Major disc.",0.45,IF(Q13="MISS",0.25,0)))))) | W13: TBD | AB13: =IF(W13="TBD","",H13*X13*IF(W13="OK",1,IF(W13="OK/Minor",0.85,IF(W13="Minor disc.",0.7,IF(W13="Major disc.",0.45,IF(W13="MISS",0.25,0)))))) | AC13: =IF(AND(Q13="TBD",W13="TBD"),"Not yet evaluated — awaiting bidder review.",IF(Q13="TBD",CONCATENATE("Bidder B: ",W13," — ",IF(AA13="","(no comment)",AA13)," | Bidder A not yet evaluated."),IF(W13="TBD",CONCATENATE("Bidder A: ",Q13," — ",IF(U13="","(no comment)",U13)," | Bidder B not yet evaluated."),CONCATENATE("Bidder A: ",Q13," — ",IF(U13="","(no comment)",U13)," || Bidder B: ",W13," — ",IF(AA13="","(no comment)",AA13)," | ",IF(Q13=W13,"Comparable disposition.","Diverging disposition — flag for negotiation.")))))
A14: 9 | B14: T1 Primary | C14: OFFER-20 | D14: Helium Leak Detection & Loss Management | E14: §4.4.7 | F14: Reliability / RAM / Service | G14: Reliability | H14: 46 | I14: 82.6531 | J14: No | K14: Submit and review the named deliverable with RTM traceability and approval status; Witnessed FAT/SAT/commissioning test against stated acceptance criteria; Functional design/configuration review and sequence/interface demonstration | L14: Offer response: Helium Leak Detection & Loss Management; Test procedure / report; Procedure / work instruction | M14: L0 Tender / Offer; L4 Installation; L1 Conceptual Design; L2 Detailed Design | N14: RTM-252..RTM-257 | O14: RTM-258..RTM-262 | P14: OK — Review breadth | Q14: TBD | V14: =IF(Q14="TBD","",H14*R14*IF(Q14="OK",1,IF(Q14="OK/Minor",0.85,IF(Q14="Minor disc.",0.7,IF(Q14="Major disc.",0.45,IF(Q14="MISS",0.25,0)))))) | W14: TBD | AB14: =IF(W14="TBD","",H14*X14*IF(W14="OK",1,IF(W14="OK/Minor",0.85,IF(W14="Minor disc.",0.7,IF(W14="Major disc.",0.45,IF(W14="MISS",0.25,0)))))) | AC14: =IF(AND(Q14="TBD",W14="TBD"),"Not yet evaluated — awaiting bidder review.",IF(Q14="TBD",CONCATENATE("Bidder B: ",W14," — ",IF(AA14="","(no comment)",AA14)," | Bidder A not yet evaluated."),IF(W14="TBD",CONCATENATE("Bidder A: ",Q14," — ",IF(U14="","(no comment)",U14)," | Bidder B not yet evaluated."),CONCATENATE("Bidder A: ",Q14," — ",IF(U14="","(no comment)",U14)," || Bidder B: ",W14," — ",IF(AA14="","(no comment)",AA14)," | ",IF(Q14=W14,"Comparable disposition.","Diverging disposition — flag for negotiation.")))))
A15: 10 | B15: T1 Primary | C15: OFFER-34 | D15: Cooling Water System Requirements | E15: §4.7.4.3.2 | F15: Performance / Process / Utilities | G15: Reliability | H15: 46 | I15: 82.6531 | J15: No | K15: Submit and review the named deliverable with RTM traceability and approval status; Calculation/model plus calibrated measurement or recorded trend; RAM/maintenance substantiation and recovery/failure-response evidence | L15: Offer response: Cooling Water System Requirements | M15: L0 Tender / Offer; L1 Conceptual Design; L2 Detailed Design | N15: RTM-426..RTM-427 | P15: OK | Q15: TBD | V15: =IF(Q15="TBD","",H15*R15*IF(Q15="OK",1,IF(Q15="OK/Minor",0.85,IF(Q15="Minor disc.",0.7,IF(Q15="Major disc.",0.45,IF(Q15="MISS",0.25,0)))))) | W15: TBD | AB15: =IF(W15="TBD","",H15*X15*IF(W15="OK",1,IF(W15="OK/Minor",0.85,IF(W15="Minor disc.",0.7,IF(W15="Major disc.",0.45,IF(W15="MISS",0.25,0)))))) | AC15: =IF(AND(Q15="TBD",W15="TBD"),"Not yet evaluated — awaiting bidder review.",IF(Q15="TBD",CONCATENATE("Bidder B: ",W15," — ",IF(AA15="","(no comment)",AA15)," | Bidder A not yet evaluated."),IF(W15="TBD",CONCATENATE("Bidder A: ",Q15," — ",IF(U15="","(no comment)",U15)," | Bidder B not yet evaluated."),CONCATENATE("Bidder A: ",Q15," — ",IF(U15="","(no comment)",U15)," || Bidder B: ",W15," — ",IF(AA15="","(no comment)",AA15)," | ",IF(Q15=W15,"Comparable disposition.","Diverging disposition — flag for negotiation.")))))
A16: 11 | B16: T1 Primary | C16: OFFER-29 | D16: Control System Obsolescence Strategy | E16: §4.6.8 | F16: Controls / Software / Management | G16: Reliability | H16: 45 | I16: 79.5918 | J16: No | K16: Submit and review the named deliverable with RTM traceability and approval status; Functional design/configuration review and sequence/interface demonstration; RAM/maintenance substantiation and recovery/failure-response evidence | L16: Offer response: Control System Obsolescence Strategy | M16: L0 Tender / Offer; L1 Conceptual Design; L2 Detailed Design | N16: RTM-346..RTM-367 | P16: OK | Q16: TBD | V16: =IF(Q16="TBD","",H16*R16*IF(Q16="OK",1,IF(Q16="OK/Minor",0.85,IF(Q16="Minor disc.",0.7,IF(Q16="Major disc.",0.45,IF(Q16="MISS",0.25,0)))))) | W16: TBD | AB16: =IF(W16="TBD","",H16*X16*IF(W16="OK",1,IF(W16="OK/Minor",0.85,IF(W16="Minor disc.",0.7,IF(W16="Major disc.",0.45,IF(W16="MISS",0.25,0)))))) | AC16: =IF(AND(Q16="TBD",W16="TBD"),"Not yet evaluated — awaiting bidder review.",IF(Q16="TBD",CONCATENATE("Bidder B: ",W16," — ",IF(AA16="","(no comment)",AA16)," | Bidder A not yet evaluated."),IF(W16="TBD",CONCATENATE("Bidder A: ",Q16," — ",IF(U16="","(no comment)",U16)," | Bidder B not yet evaluated."),CONCATENATE("Bidder A: ",Q16," — ",IF(U16="","(no comment)",U16)," || Bidder B: ",W16," — ",IF(AA16="","(no comment)",AA16)," | ",IF(Q16=W16,"Comparable disposition.","Diverging disposition — flag for negotiation.")))))
A17: 12 | B17: T1 Primary | C17: OFFER-04 | D17: Cooldown & Thermal Performance Modelling | E17: §4.2.2.2 | F17: Performance / Process / Utilities | G17: Performance | H17: 44 | I17: 76.5306 | J17: No | K17: Submit and review the named deliverable with RTM traceability and approval status; Calculation/model plus calibrated measurement or recorded trend; Document review, inspection, certification, audit or traceable QC record | L17: Offer response: Cooldown & Thermal Performance Modelling | M17: L0 Tender / Offer; L1 Conceptual Design; L2 Detailed Design | N17: RTM-019..RTM-022 | P17: OK | Q17: TBD | V17: =IF(Q17="TBD","",H17*R17*IF(Q17="OK",1,IF(Q17="OK/Minor",0.85,IF(Q17="Minor disc.",0.7,IF(Q17="Major disc.",0.45,IF(Q17="MISS",0.25,0)))))) | W17: TBD | AB17: =IF(W17="TBD","",H17*X17*IF(W17="OK",1,IF(W17="OK/Minor",0.85,IF(W17="Minor disc.",0.7,IF(W17="Major disc.",0.45,IF(W17="MISS",0.25,0)))))) | AC17: =IF(AND(Q17="TBD",W17="TBD"),"Not yet evaluated — awaiting bidder review.",IF(Q17="TBD",CONCATENATE("Bidder B: ",W17," — ",IF(AA17="","(no comment)",AA17)," | Bidder A not yet evaluated."),IF(W17="TBD",CONCATENATE("Bidder A: ",Q17," — ",IF(U17="","(no comment)",U17)," | Bidder B not yet evaluated."),CONCATENATE("Bidder A: ",Q17," — ",IF(U17="","(no comment)",U17)," || Bidder B: ",W17," — ",IF(AA17="","(no comment)",AA17)," | ",IF(Q17=W17,"Comparable disposition.","Diverging disposition — flag for negotiation.")))))
A18: 13 | B18: T1 Primary | C18: OFFER-05 | D18: Operational Procedure Strategy (Auto vs Manual) | E18: §4.2.2.4.1 | F18: Controls / Software / Management | G18: Performance | H18: 44 | I18: 76.5306 | J18: No | K18: Submit and review the named deliverable with RTM traceability and approval status; Calculation/model plus calibrated measurement or recorded trend; Functional design/configuration review and sequence/interface demonstration | L18: Offer response: Operational Procedure Strategy (Auto vs Manual); Procedure / work instruction | M18: L0 Tender / Offer; L1 Conceptual Design; L2 Detailed Design | N18: RTM-025..RTM-027 | P18: OK | Q18: TBD | V18: =IF(Q18="TBD","",H18*R18*IF(Q18="OK",1,IF(Q18="OK/Minor",0.85,IF(Q18="Minor disc.",0.7,IF(Q18="Major disc.",0.45,IF(Q18="MISS",0.25,0)))))) | W18: TBD | AB18: =IF(W18="TBD","",H18*X18*IF(W18="OK",1,IF(W18="OK/Minor",0.85,IF(W18="Minor disc.",0.7,IF(W18="Major disc.",0.45,IF(W18="MISS",0.25,0)))))) | AC18: =IF(AND(Q18="TBD",W18="TBD"),"Not yet evaluated — awaiting bidder review.",IF(Q18="TBD",CONCATENATE("Bidder B: ",W18," — ",IF(AA18="","(no comment)",AA18)," | Bidder A not yet evaluated."),IF(W18="TBD",CONCATENATE("Bidder A: ",Q18," — ",IF(U18="","(no comment)",U18)," | Bidder B not yet evaluated."),CONCATENATE("Bidder A: ",Q18," — ",IF(U18="","(no comment)",U18)," || Bidder B: ",W18," — ",IF(AA18="","(no comment)",AA18)," | ",IF(Q18=W18,"Comparable disposition.","Diverging disposition — flag for negotiation.")))))
A19: 14 | B19: T1 Primary | C19: OFFER-27 | D19: Programming Standards & Language Strategy | E19: §4.6.7 | F19: Controls / Software / Management | G19: Functional | H19: 41.3333 | I19: 73.4694 | J19: No | K19: Submit and review the named deliverable with RTM traceability and approval status; Witnessed FAT/SAT/commissioning test against stated acceptance criteria; Functional design/configuration review and sequence/interface demonstration | L19: Offer response: Programming Standards & Language Strategy | M19: L0 Tender / Offer; L1 Conceptual Design; L2 Detailed Design | N19: RTM-340..RTM-341; RTM-343..RTM-344 | O19: RTM-334..RTM-339; RTM-342; RTM-345 | P19: OK | Q19: TBD | V19: =IF(Q19="TBD","",H19*R19*IF(Q19="OK",1,IF(Q19="OK/Minor",0.85,IF(Q19="Minor disc.",0.7,IF(Q19="Major disc.",0.45,IF(Q19="MISS",0.25,0)))))) | W19: TBD | AB19: =IF(W19="TBD","",H19*X19*IF(W19="OK",1,IF(W19="OK/Minor",0.85,IF(W19="Minor disc.",0.7,IF(W19="Major disc.",0.45,IF(W19="MISS",0.25,0)))))) | AC19: =IF(AND(Q19="TBD",W19="TBD"),"Not yet evaluated — awaiting bidder review.",IF(Q19="TBD",CONCATENATE("Bidder B: ",W19," — ",IF(AA19="","(no comment)",AA19)," | Bidder A not yet evaluated."),IF(W19="TBD",CONCATENATE("Bidder A: ",Q19," — ",IF(U19="","(no comment)",U19)," | Bidder B not yet evaluated."),CONCATENATE("Bidder A: ",Q19," — ",IF(U19="","(no comment)",U19)," || Bidder B: ",W19," — ",IF(AA19="","(no comment)",AA19)," | ",IF(Q19=W19,"Comparable disposition.","Diverging disposition — flag for negotiation.")))))
A20: 15 | B20: T1 Primary | C20: OFFER-33 | D20: Electrical System Design & Load Analysis | E20: §4.7.3.1 | F20: Controls / Software / Management | G20: Reliability | H20: 38.6667 | I20: 70.4082 | J20: No | K20: Submit and review the named deliverable with RTM traceability and approval status; Calculation/model plus calibrated measurement or recorded trend; RAM/maintenance substantiation and recovery/failure-response evidence | L20: Offer response: Electrical System Design & Load Analysis; Drawing / diagram; List / register / matrix | M20: L0 Tender / Offer; L1 Conceptual Design; L2 Detailed Design | N20: RTM-401..RTM-402 | P20: OK | Q20: TBD | V20: =IF(Q20="TBD","",H20*R20*IF(Q20="OK",1,IF(Q20="OK/Minor",0.85,IF(Q20="Minor disc.",0.7,IF(Q20="Major disc.",0.45,IF(Q20="MISS",0.25,0)))))) | W20: TBD | AB20: =IF(W20="TBD","",H20*X20*IF(W20="OK",1,IF(W20="OK/Minor",0.85,IF(W20="Minor disc.",0.7,IF(W20="Major disc.",0.45,IF(W20="MISS",0.25,0)))))) | AC20: =IF(AND(Q20="TBD",W20="TBD"),"Not yet evaluated — awaiting bidder review.",IF(Q20="TBD",CONCATENATE("Bidder B: ",W20," — ",IF(AA20="","(no comment)",AA20)," | Bidder A not yet evaluated."),IF(W20="TBD",CONCATENATE("Bidder A: ",Q20," — ",IF(U20="","(no comment)",U20)," | Bidder B not yet evaluated."),CONCATENATE("Bidder A: ",Q20," — ",IF(U20="","(no comment)",U20)," || Bidder B: ",W20," — ",IF(AA20="","(no comment)",AA20)," | ",IF(Q20=W20,"Comparable disposition.","Diverging disposition — flag for negotiation.")))))
A21: 16 | B21: T1 Primary | C21: OFFER-41 | D21: Spare Parts & Critical Components Strategy | E21: §4.14.3 | F21: Reliability / RAM / Service | G21: Reliability | H21: 38.6667 | I21: 70.4082 | J21: No | K21: Submit and review the named deliverable with RTM traceability and approval status; RAM/maintenance substantiation and recovery/failure-response evidence | L21: Offer response: Spare Parts & Critical Components Strategy; List / register / matrix | M21: L0 Tender / Offer; L1 Conceptual Design; L2 Detailed Design | N21: RTM-560..RTM-562 | P21: OK | Q21: TBD | V21: =IF(Q21="TBD","",H21*R21*IF(Q21="OK",1,IF(Q21="OK/Minor",0.85,IF(Q21="Minor disc.",0.7,IF(Q21="Major disc.",0.45,IF(Q21="MISS",0.25,0)))))) | W21: TBD | AB21: =IF(W21="TBD","",H21*X21*IF(W21="OK",1,IF(W21="OK/Minor",0.85,IF(W21="Minor disc.",0.7,IF(W21="Major disc.",0.45,IF(W21="MISS",0.25,0)))))) | AC21: =IF(AND(Q21="TBD",W21="TBD"),"Not yet evaluated — awaiting bidder review.",IF(Q21="TBD",CONCATENATE("Bidder B: ",W21," — ",IF(AA21="","(no comment)",AA21)," | Bidder A not yet evaluated."),IF(W21="TBD",CONCATENATE("Bidder A: ",Q21," — ",IF(U21="","(no comment)",U21)," | Bidder B not yet evaluated."),CONCATENATE("Bidder A: ",Q21," — ",IF(U21="","(no comment)",U21)," || Bidder B: ",W21," — ",IF(AA21="","(no comment)",AA21)," | ",IF(Q21=W21,"Comparable disposition.","Diverging disposition — flag for negotiation.")))))
A22: 17 | B22: T2 Secondary | C22: OFFER-06 | D22: LHe Filling & Emptying Performance | E22: §4.2.2.4.3 | F22: Performance / Process / Utilities | G22: Performance | H22: 36 | I22: 66.3265 | J22: No | K22: Submit and review the named deliverable with RTM traceability and approval status; Calculation/model plus calibrated measurement or recorded trend | L22: Offer response: LHe Filling & Emptying Performance | M22: L0 Tender / Offer; L1 Conceptual Design; L2 Detailed Design | N22: RTM-030..RTM-033 | P22: OK | Q22: TBD | V22: =IF(Q22="TBD","",H22*R22*IF(Q22="OK",1,IF(Q22="OK/Minor",0.85,IF(Q22="Minor disc.",0.7,IF(Q22="Major disc.",0.45,IF(Q22="MISS",0.25,0)))))) | W22: TBD | AB22: =IF(W22="TBD","",H22*X22*IF(W22="OK",1,IF(W22="OK/Minor",0.85,IF(W22="Minor disc.",0.7,IF(W22="Major disc.",0.45,IF(W22="MISS",0.25,0)))))) | AC22: =IF(AND(Q22="TBD",W22="TBD"),"Not yet evaluated — awaiting bidder review.",IF(Q22="TBD",CONCATENATE("Bidder B: ",W22," — ",IF(AA22="","(no comment)",AA22)," | Bidder A not yet evaluated."),IF(W22="TBD",CONCATENATE("Bidder A: ",Q22," — ",IF(U22="","(no comment)",U22)," | Bidder B not yet evaluated."),CONCATENATE("Bidder A: ",Q22," — ",IF(U22="","(no comment)",U22)," || Bidder B: ",W22," — ",IF(AA22="","(no comment)",AA22)," | ",IF(Q22=W22,"Comparable disposition.","Diverging disposition — flag for negotiation.")))))
A23: 18 | B23: T2 Secondary | C23: OFFER-37 | D23: Digital Twin / Simulation Strategy | E23: §4.8.2 | F23: Controls / Software / Management | G23: Functional | H23: 36 | I23: 66.3265 | J23: No | K23: Submit and review the named deliverable with RTM traceability and approval status; Witnessed FAT/SAT/commissioning test against stated acceptance criteria; Document review, inspection, certification, audit or traceable QC record | L23: Offer response: Digital Twin / Simulation Strategy; Digital Process Model / Digital Twin | M23: L0 Tender / Offer; L1 Conceptual Design; L2 Detailed Design | N23: RTM-450..RTM-451 | P23: OK | Q23: TBD | V23: =IF(Q23="TBD","",H23*R23*IF(Q23="OK",1,IF(Q23="OK/Minor",0.85,IF(Q23="Minor disc.",0.7,IF(Q23="Major disc.",0.45,IF(Q23="MISS",0.25,0)))))) | W23: TBD | AB23: =IF(W23="TBD","",H23*X23*IF(W23="OK",1,IF(W23="OK/Minor",0.85,IF(W23="Minor disc.",0.7,IF(W23="Major disc.",0.45,IF(W23="MISS",0.25,0)))))) | AC23: =IF(AND(Q23="TBD",W23="TBD"),"Not yet evaluated — awaiting bidder review.",IF(Q23="TBD",CONCATENATE("Bidder B: ",W23," — ",IF(AA23="","(no comment)",AA23)," | Bidder A not yet evaluated."),IF(W23="TBD",CONCATENATE("Bidder A: ",Q23," — ",IF(U23="","(no comment)",U23)," | Bidder B not yet evaluated."),CONCATENATE("Bidder A: ",Q23," — ",IF(U23="","(no comment)",U23)," || Bidder B: ",W23," — ",IF(AA23="","(no comment)",AA23)," | ",IF(Q23=W23,"Comparable disposition.","Diverging disposition — flag for negotiation.")))))
A24: 19 | B24: T2 Secondary | C24: OFFER-43 | D24: Maintenance Effort & Intervention Estimation | E24: §4.15 | F24: Reliability / RAM / Service | G24: Reliability | H24: 35.6667 | I24: 63.2653 | J24: No | K24: Submit and review the named deliverable with RTM traceability and approval status; RAM/maintenance substantiation and recovery/failure-response evidence | L24: Offer response: Maintenance Effort & Intervention Estimation | M24: L0 Tender / Offer; L1 Conceptual Design; L2 Detailed Design | O24: RTM-563..RTM-565 | P24: Review — accept context | Q24: TBD | V24: =IF(Q24="TBD","",H24*R24*IF(Q24="OK",1,IF(Q24="OK/Minor",0.85,IF(Q24="Minor disc.",0.7,IF(Q24="Major disc.",0.45,IF(Q24="MISS",0.25,0)))))) | W24: TBD | AB24: =IF(W24="TBD","",H24*X24*IF(W24="OK",1,IF(W24="OK/Minor",0.85,IF(W24="Minor disc.",0.7,IF(W24="Major disc.",0.45,IF(W24="MISS",0.25,0)))))) | AC24: =IF(AND(Q24="TBD",W24="TBD"),"Not yet evaluated — awaiting bidder review.",IF(Q24="TBD",CONCATENATE("Bidder B: ",W24," — ",IF(AA24="","(no comment)",AA24)," | Bidder A not yet evaluated."),IF(W24="TBD",CONCATENATE("Bidder A: ",Q24," — ",IF(U24="","(no comment)",U24)," | Bidder B not yet evaluated."),CONCATENATE("Bidder A: ",Q24," — ",IF(U24="","(no comment)",U24)," || Bidder B: ",W24," — ",IF(AA24="","(no comment)",AA24)," | ",IF(Q24=W24,"Comparable disposition.","Diverging disposition — flag for negotiation.")))))
